<?xml version='1.0'?>
<robot
  name="moveo">	

  
  <!-- BASE LINK -->
  <link
    name="base_link">
   
    <inertial>
      <origin
        xyz="0.005 0.065 0.003"
        rpy="0 0 0" />
      <mass
        value="5.0" />
      <inertia
        ixx="0.142"
	ixy="0.002"
	ixz="1.0E-09"
	iyy="0.139"
	iyz="0.004"
	izz="0.273"/>
        
    </inertial>
    
    <visual>
      <origin
        xyz="0 0 0"
        rpy="0 0 0" />
      <geometry>
        <mesh
          filename="package://iteration_3/meshes/base_link.stl" />
      </geometry>
      <material
        name="">
        <color
          rgba="0.75294 0.75294 0.75294 1" />
      </material>
    </visual>
    
    <collision>
      <origin
        xyz="0 0 0"
        rpy="0 0 0" />
      <geometry>
        <mesh
          filename="package://iteration_3/meshes/base_link.stl" />
      </geometry>
    </collision>
  </link>
  
  
  
    
  <link name="world"/>
  
  <joint name="fixed" type="fixed">
    <parent link="world"/>
    <child link="base_link"/>
  </joint>
  
  

  <!-- DUMMY LINK -->
  
  
  <link
    name="odom">
    <inertial>
      <origin
        xyz="0.034155 -0.20591 -0.049641"
        rpy="0 0 0" />
      <mass
        value="8.0643" />
      <inertia
        ixx="0.11291"
        ixy="0.00066071"
        ixz="1.0E-09"
        iyy="0.089946"
        iyz="0.011461"
        izz="0.19187" />
    </inertial>
   </link>

  <joint
    name="odom_joint"
    type="fixed">
    <origin
      xyz="0 0 0"
      rpy="0 0 0" />
    <parent
      link="base_link" />
    <child
      link="odom" />
  </joint>







  <!--   LINK 1   -->

  <link
    name="Link_1">
    <inertial>
      <origin
        xyz="-1.184E-05 -8.007E-06 0.161"
        rpy="0 0 0" />
      <mass
        value="3" />
      <inertia
        ixx="0.007"
	ixy="4.973E-09"
	ixz="1.485E-06"
	iyy="0.011"
	iyz="1.0E-09"
	izz="0.008" />
    </inertial>
    
    <visual>
      <origin
        xyz="0 0 0"
        rpy="0 0 0" />
      <geometry>
        <mesh
          filename="package://iteration_3/meshes/Link_1.stl" />
      </geometry>
      <material
        name="">
        <color
          rgba="0.75294 0.75294 0.75294 1" />
      </material>
    </visual>
    
    <collision>
      <origin
        xyz="0 0 0"
        rpy="0 0 0" />
      <geometry>
        <mesh
          filename="package://iteration_3/meshes/Link_1.stl" />
      </geometry>
    </collision>
  </link>
  
  
  
  <joint
    name="Joint_1"
    type="revolute">
    <origin
      xyz="0 0 0.092"
      rpy="0 0 0" />
    <parent
      link="base_link" />
    <child
      link="Link_1" />
    <axis
      xyz="0 0 1" />
    <limit
      lower="-1.5707"
      upper="1.5707"
      effort="5.0"
      velocity="1.0" />
  </joint>
  


</robot>


  

